Workbook

Sheet Painel
B2: RADAR LOW TICKET — ofertas mineradas
B4: Base: vault Obsidian /lowticket — 123 registros (103 ofertas + 20 angulos). iGreen fora. Notas recalculam sozinhas se voce editar a aba Ofertas.
B6: Registros | D6: Quentes (nota >= 7) | F6: Escalaveis (>= 7) | H6: Potencial Alta | J6: Rodando agora | L6: Veredito replicar | N6: Criativos ativos | P6: Ticket medio (R$)
B7: =COUNTA(Ofertas!A2:A124) -> 123 | D7: =COUNTIF(Ofertas!B2:B124,">=7") -> 12 | F7: =COUNTIF(Ofertas!C2:C124,">=7") -> 15 | H7: =COUNTIF(Ofertas!E2:E124,"Alta") -> 6 | J7: =COUNTIF(Ofertas!N2:N124,"ativa") -> 9 | L7: =COUNTIF(Ofertas!O2:O124,"replicar") -> 14 | N7: =SUM(Ofertas!L2:L124) -> 100 | P7: =ROUND(AVERAGEIF(Ofertas!S2:S124,">0"),0) -> 72
B10: TOP 12 — maior nota geral
B11: # | C11: Oferta | D11: Quente | E11: Escalavel | F11: Nota geral | G11: Potencial | H11: Criativos | I11: Dias no ar | J11: Nicho | K11: Pagina
B12: 1 | C12: Danca dos Noivos Online | D12: =INDEX(Ofertas!B:B,MATCH($C12,Ofertas!$A:$A,0)) -> 8.5 | E12: =INDEX(Ofertas!C:C,MATCH($C12,Ofertas!$A:$A,0)) -> 6.7 | F12: =INDEX(Ofertas!D:D,MATCH($C12,Ofertas!$A:$A,0)) -> 7.5 | G12: =INDEX(Ofertas!E:E,MATCH($C12,Ofertas!$A:$A,0)) -> Alta | H12: =INDEX(Ofertas!L:L,MATCH($C12,Ofertas!$A:$A,0)) -> 9 | I12: =INDEX(Ofertas!M:M,MATCH($C12,Ofertas!$A:$A,0)) -> 509 | J12: =INDEX(Ofertas!P:P,MATCH($C12,Ofertas!$A:$A,0)) -> danca | K12: abrir
B13: 2 | C13: +150 Bonecas de Papel — Maria Criativa | D13: =INDEX(Ofertas!B:B,MATCH($C13,Ofertas!$A:$A,0)) -> 8 | E13: =INDEX(Ofertas!C:C,MATCH($C13,Ofertas!$A:$A,0)) -> 6.9 | F13: =INDEX(Ofertas!D:D,MATCH($C13,Ofertas!$A:$A,0)) -> 7.4 | G13: =INDEX(Ofertas!E:E,MATCH($C13,Ofertas!$A:$A,0)) -> Alta | H13: =INDEX(Ofertas!L:L,MATCH($C13,Ofertas!$A:$A,0)) -> 9 | I13: =INDEX(Ofertas!M:M,MATCH($C13,Ofertas!$A:$A,0)) -> 54 | J13: =INDEX(Ofertas!P:P,MATCH($C13,Ofertas!$A:$A,0)) -> comportamento-infantil | K13: abrir
B14: 3 | C14: Retrato da Alma Gemea | D14: =INDEX(Ofertas!B:B,MATCH($C14,Ofertas!$A:$A,0)) -> 8 | E14: =INDEX(Ofertas!C:C,MATCH($C14,Ofertas!$A:$A,0)) -> 6.5 | F14: =INDEX(Ofertas!D:D,MATCH($C14,Ofertas!$A:$A,0)) -> 7.2 | G14: =INDEX(Ofertas!E:E,MATCH($C14,Ofertas!$A:$A,0)) -> Alta | H14: =INDEX(Ofertas!L:L,MATCH($C14,Ofertas!$A:$A,0)) -> 0 | I14: =INDEX(Ofertas!M:M,MATCH($C14,Ofertas!$A:$A,0)) -> 1826 | J14: =INDEX(Ofertas!P:P,MATCH($C14,Ofertas!$A:$A,0)) -> esoterico | K14: abrir
B15: 4 | C15: Colecao Completa de Caligrafia 1o ao 6o ano — 380 atividades | D15: =INDEX(Ofertas!B:B,MATCH($C15,Ofertas!$A:$A,0)) -> 7.5 | E15: =INDEX(Ofertas!C:C,MATCH($C15,Ofertas!$A:$A,0)) -> 6.8 | F15: =INDEX(Ofertas!D:D,MATCH($C15,Ofertas!$A:$A,0)) -> 7.1 | G15: =INDEX(Ofertas!E:E,MATCH($C15,Ofertas!$A:$A,0)) -> Alta | H15: =INDEX(Ofertas!L:L,MATCH($C15,Ofertas!$A:$A,0)) -> 8 | I15: =INDEX(Ofertas!M:M,MATCH($C15,Ofertas!$A:$A,0)) -> 123 | J15: =INDEX(Ofertas!P:P,MATCH($C15,Ofertas!$A:$A,0)) -> material-pedagogico | K15: abrir
B16: 5 | C16: Little Genius — Kit de 235+ atividades educativas | D16: =INDEX(Ofertas!B:B,MATCH($C16,Ofertas!$A:$A,0)) -> 6.5 | E16: =INDEX(Ofertas!C:C,MATCH($C16,Ofertas!$A:$A,0)) -> 7.5 | F16: =INDEX(Ofertas!D:D,MATCH($C16,Ofertas!$A:$A,0)) -> 7.1 | G16: =INDEX(Ofertas!E:E,MATCH($C16,Ofertas!$A:$A,0)) -> Alta | H16: =INDEX(Ofertas!L:L,MATCH($C16,Ofertas!$A:$A,0)) -> 1 | I16: =INDEX(Ofertas!M:M,MATCH($C16,Ofertas!$A:$A,0)) -> 76 | J16: =INDEX(Ofertas!P:P,MATCH($C16,Ofertas!$A:$A,0)) -> material-pedagogico | K16: abrir
B17: 6 | C17: Kit Grafismo Fonetico — Leitura Facil | D17: =INDEX(Ofertas!B:B,MATCH($C17,Ofertas!$A:$A,0)) -> 8 | E17: =INDEX(Ofertas!C:C,MATCH($C17,Ofertas!$A:$A,0)) -> 6.1 | F17: =INDEX(Ofertas!D:D,MATCH($C17,Ofertas!$A:$A,0)) -> 7 | G17: =INDEX(Ofertas!E:E,MATCH($C17,Ofertas!$A:$A,0)) -> Alta | H17: =INDEX(Ofertas!L:L,MATCH($C17,Ofertas!$A:$A,0)) -> 10 | I17: =INDEX(Ofertas!M:M,MATCH($C17,Ofertas!$A:$A,0)) -> 39 | J17: =INDEX(Ofertas!P:P,MATCH($C17,Ofertas!$A:$A,0)) -> material-pedagogico | K17: —
B18: 7 | C18: Missa em Atividades — kit catolico infantil imprimivel | D18: =INDEX(Ofertas!B:B,MATCH($C18,Ofertas!$A:$A,0)) -> 7 | E18: =INDEX(Ofertas!C:C,MATCH($C18,Ofertas!$A:$A,0)) -> 6.7 | F18: =INDEX(Ofertas!D:D,MATCH($C18,Ofertas!$A:$A,0)) -> 6.8 | G18: =INDEX(Ofertas!E:E,MATCH($C18,Ofertas!$A:$A,0)) -> Media | H18: =INDEX(Ofertas!L:L,MATCH($C18,Ofertas!$A:$A,0)) -> 3 | I18: =INDEX(Ofertas!M:M,MATCH($C18,Ofertas!$A:$A,0)) -> 35 | J18: =INDEX(Ofertas!P:P,MATCH($C18,Ofertas!$A:$A,0)) -> comportamento-infantil | K18: —
B19: 8 | C19: Cantigas da Bailarina — repertorio pronto para Baby Class | D19: =INDEX(Ofertas!B:B,MATCH($C19,Ofertas!$A:$A,0)) -> 7 | E19: =INDEX(Ofertas!C:C,MATCH($C19,Ofertas!$A:$A,0)) -> 6.2 | F19: =INDEX(Ofertas!D:D,MATCH($C19,Ofertas!$A:$A,0)) -> 6.6 | G19: =INDEX(Ofertas!E:E,MATCH($C19,Ofertas!$A:$A,0)) -> Media | H19: =INDEX(Ofertas!L:L,MATCH($C19,Ofertas!$A:$A,0)) -> 11 | I19: =INDEX(Ofertas!M:M,MATCH($C19,Ofertas!$A:$A,0)) -> 9 | J19: =INDEX(Ofertas!P:P,MATCH($C19,Ofertas!$A:$A,0)) -> danca | K19: abrir
B20: 9 | C20: Angulo — material pronto para quem ENSINA danca | D20: =INDEX(Ofertas!B:B,MATCH($C20,Ofertas!$A:$A,0)) -> 7 | E20: =INDEX(Ofertas!C:C,MATCH($C20,Ofertas!$A:$A,0)) -> 6.2 | F20: =INDEX(Ofertas!D:D,MATCH($C20,Ofertas!$A:$A,0)) -> 6.6 | G20: =INDEX(Ofertas!E:E,MATCH($C20,Ofertas!$A:$A,0)) -> Media | H20: =INDEX(Ofertas!L:L,MATCH($C20,Ofertas!$A:$A,0)) -> 19 | I20: =INDEX(Ofertas!M:M,MATCH($C20,Ofertas!$A:$A,0)) -> 10 | J20: =INDEX(Ofertas!P:P,MATCH($C20,Ofertas!$A:$A,0)) -> danca | K20: —
B21: 10 | C21: Casinha dos Sonhos — casinha de papel imprimivel | D21: =INDEX(Ofertas!B:B,MATCH($C21,Ofertas!$A:$A,0)) -> 6 | E21: =INDEX(Ofertas!C:C,MATCH($C21,Ofertas!$A:$A,0)) -> 6.9 | F21: =INDEX(Ofertas!D:D,MATCH($C21,Ofertas!$A:$A,0)) -> 6.5 | G21: =INDEX(Ofertas!E:E,MATCH($C21,Ofertas!$A:$A,0)) -> Media | H21: =INDEX(Ofertas!L:L,MATCH($C21,Ofertas!$A:$A,0)) -> 2 | I21: =INDEX(Ofertas!M:M,MATCH($C21,Ofertas!$A:$A,0)) -> 42 | J21: =INDEX(Ofertas!P:P,MATCH($C21,Ofertas!$A:$A,0)) -> comportamento-infantil | K21: abrir
B22: 11 | C22: Kit de Alfabetizacao Alfa Kids — 2.750 atividades | D22: =INDEX(Ofertas!B:B,MATCH($C22,Ofertas!$A:$A,0)) -> 6.5 | E22: =INDEX(Ofertas!C:C,MATCH($C22,Ofertas!$A:$A,0)) -> 6.1 | F22: =INDEX(Ofertas!D:D,MATCH($C22,Ofertas!$A:$A,0)) -> 6.3 | G22: =INDEX(Ofertas!E:E,MATCH($C22,Ofertas!$A:$A,0)) -> Media | H22: =INDEX(Ofertas!L:L,MATCH($C22,Ofertas!$A:$A,0)) -> 2 | I22: =INDEX(Ofertas!M:M,MATCH($C22,Ofertas!$A:$A,0)) -> 107 | J22: =INDEX(Ofertas!P:P,MATCH($C22,Ofertas!$A:$A,0)) -> material-pedagogico | K22: —
B23: 12 | C23: Clube da Pedagogia — kit 3.000+ atividades BNCC | D23: =INDEX(Ofertas!B:B,MATCH($C23,Ofertas!$A:$A,0)) -> 6.5 | E23: =INDEX(Ofertas!C:C,MATCH($C23,Ofertas!$A:$A,0)) -> 6.1 | F23: =INDEX(Ofertas!D:D,MATCH($C23,Ofertas!$A:$A,0)) -> 6.3 | G23: =INDEX(Ofertas!E:E,MATCH($C23,Ofertas!$A:$A,0)) -> Media | H23: =INDEX(Ofertas!L:L,MATCH($C23,Ofertas!$A:$A,0)) -> 1 | I23: =INDEX(Ofertas!M:M,MATCH($C23,Ofertas!$A:$A,0)) -> 74 | J23: =INDEX(Ofertas!P:P,MATCH($C23,Ofertas!$A:$A,0)) -> material-pedagogico | K23: abrir
B26: Nichos — onde o dinheiro aparece | J26: Como as notas sao calculadas
B27: Nicho | C27: Ofertas | D27: Nota media | E27: Quente media | F27: Criativos ativos | G27: Ticket medio (R$) | H27: Barra
B28: comportamento-infantil | C28: =COUNTIF(Ofertas!$P$2:$P$124,$B28) -> 23 | D28: =IFERROR(ROUND(AVERAGEIF(Ofertas!$P$2:$P$124,$B28,Ofertas!$D$2:$D$124),1),"") -> 4.4 | E28: =IFERROR(ROUND(AVERAGEIF(Ofertas!$P$2:$P$124,$B28,Ofertas!$B$2:$B$124),1),"") -> 1.7 | F28: =SUMIF(Ofertas!$P$2:$P$124,$B28,Ofertas!$L$2:$L$124) -> 17 | G28: =IFERROR(ROUND(AVERAGEIF(Ofertas!$P$2:$P$124,$B28,Ofertas!$S$2:$S$124),0),"") -> 34 | H28: =REPT("|",C28) -> ||||||||||||||||||||||| | J28: QUENTE (0-10) = prova de que esta rodando agora
B29: danca | C29: =COUNTIF(Ofertas!$P$2:$P$124,$B29) -> 13 | D29: =IFERROR(ROUND(AVERAGEIF(Ofertas!$P$2:$P$124,$B29,Ofertas!$D$2:$D$124),1),"") -> 5.8 | E29: =IFERROR(ROUND(AVERAGEIF(Ofertas!$P$2:$P$124,$B29,Ofertas!$B$2:$B$124),1),"") -> 6.2 | F29: =SUMIF(Ofertas!$P$2:$P$124,$B29,Ofertas!$L$2:$L$124) -> 58 | G29: =IFERROR(ROUND(AVERAGEIF(Ofertas!$P$2:$P$124,$B29,Ofertas!$S$2:$S$124),0),"") -> 109 | H29: =REPT("|",C29) -> ||||||||||||| | J29: status (ativa 5 / nova 4 / esfriando 2 / morta 0)
B30: material-pedagogico | C30: =COUNTIF(Ofertas!$P$2:$P$124,$B30) -> 11 | D30: =IFERROR(ROUND(AVERAGEIF(Ofertas!$P$2:$P$124,$B30,Ofertas!$D$2:$D$124),1),"") -> 6.1 | E30: =IFERROR(ROUND(AVERAGEIF(Ofertas!$P$2:$P$124,$B30,Ofertas!$B$2:$B$124),1),"") -> 5.8 | F30: =SUMIF(Ofertas!$P$2:$P$124,$B30,Ofertas!$L$2:$L$124) -> 25 | G30: =IFERROR(ROUND(AVERAGEIF(Ofertas!$P$2:$P$124,$B30,Ofertas!$S$2:$S$124),0),"") -> 27 | H30: =REPT("|",C30) -> ||||||||||| | J30: + criativos ativos (>=9 vale 3, >=3 vale 2, >=1 vale 1)
B31: religioso | C31: =COUNTIF(Ofertas!$P$2:$P$124,$B31) -> 11 | D31: =IFERROR(ROUND(AVERAGEIF(Ofertas!$P$2:$P$124,$B31,Ofertas!$D$2:$D$124),1),"") -> 3.8 | E31: =IFERROR(ROUND(AVERAGEIF(Ofertas!$P$2:$P$124,$B31,Ofertas!$B$2:$B$124),1),"") -> 0.2 | F31: =SUMIF(Ofertas!$P$2:$P$124,$B31,Ofertas!$L$2:$L$124) -> 0 | G31: =IFERROR(ROUND(AVERAGEIF(Ofertas!$P$2:$P$124,$B31,Ofertas!$S$2:$S$124),0),"") -> 98 | H31: =REPT("|",C31) -> ||||||||||| | J31: + tempo no ar (>=60d 1,5 / >=30d 1 / >=14d 0,5)
B32: ganhar-dinheiro | C32: =COUNTIF(Ofertas!$P$2:$P$124,$B32) -> 7 | D32: =IFERROR(ROUND(AVERAGEIF(Ofertas!$P$2:$P$124,$B32,Ofertas!$D$2:$D$124),1),"") -> 4 | E32: =IFERROR(ROUND(AVERAGEIF(Ofertas!$P$2:$P$124,$B32,Ofertas!$B$2:$B$124),1),"") -> 3.4 | F32: =SUMIF(Ofertas!$P$2:$P$124,$B32,Ofertas!$L$2:$L$124) -> 0 | G32: =IFERROR(ROUND(AVERAGEIF(Ofertas!$P$2:$P$124,$B32,Ofertas!$S$2:$S$124),0),"") -> 91 | H32: =REPT("|",C32) -> ||||||| | J32: + reclamacoes no ReclameAqui (>=50 1,5 / >=10 1 / >=1 0,5)
B33: esoterico | C33: =COUNTIF(Ofertas!$P$2:$P$124,$B33) -> 4 | D33: =IFERROR(ROUND(AVERAGEIF(Ofertas!$P$2:$P$124,$B33,Ofertas!$D$2:$D$124),1),"") -> 5.7 | E33: =IFERROR(ROUND(AVERAGEIF(Ofertas!$P$2:$P$124,$B33,Ofertas!$B$2:$B$124),1),"") -> 4.9 | F33: =SUMIF(Ofertas!$P$2:$P$124,$B33,Ofertas!$L$2:$L$124) -> 0 | G33: =IFERROR(ROUND(AVERAGEIF(Ofertas!$P$2:$P$124,$B33,Ofertas!$S$2:$S$124),0),"") -> 18 | H33: =REPT("|",C33) -> |||| | J33: + apareceu em 4+ rodadas (0,5)
B34: certificacao | C34: =COUNTIF(Ofertas!$P$2:$P$124,$B34) -> 4 | D34: =IFERROR(ROUND(AVERAGEIF(Ofertas!$P$2:$P$124,$B34,Ofertas!$D$2:$D$124),1),"") -> 5.6 | E34: =IFERROR(ROUND(AVERAGEIF(Ofertas!$P$2:$P$124,$B34,Ofertas!$B$2:$B$124),1),"") -> 6.1 | F34: =SUMIF(Ofertas!$P$2:$P$124,$B34,Ofertas!$L$2:$L$124) -> 0 | G34: =IFERROR(ROUND(AVERAGEIF(Ofertas!$P$2:$P$124,$B34,Ofertas!$S$2:$S$124),0),"") -> 92 | H34: =REPT("|",C34) -> ||||
B35: renda-celular-cashback | C35: =COUNTIF(Ofertas!$P$2:$P$124,$B35) -> 4 | D35: =IFERROR(ROUND(AVERAGEIF(Ofertas!$P$2:$P$124,$B35,Ofertas!$D$2:$D$124),1),"") -> 2.6 | E35: =IFERROR(ROUND(AVERAGEIF(Ofertas!$P$2:$P$124,$B35,Ofertas!$B$2:$B$124),1),"") -> 1 | F35: =SUMIF(Ofertas!$P$2:$P$124,$B35,Ofertas!$L$2:$L$124) -> 0 | G35: =IFERROR(ROUND(AVERAGEIF(Ofertas!$P$2:$P$124,$B35,Ofertas!$S$2:$S$124),0),"") -> 66 | H35: =REPT("|",C35) -> |||| | J35: ESCALAVEL (0-10) = quanto voce consegue refazer e lucrar
B36: saude-estetica-fitness | C36: =COUNTIF(Ofertas!$P$2:$P$124,$B36) -> 3 | D36: =IFERROR(ROUND(AVERAGEIF(Ofertas!$P$2:$P$124,$B36,Ofertas!$D$2:$D$124),1),"") -> 4.1 | E36: =IFERROR(ROUND(AVERAGEIF(Ofertas!$P$2:$P$124,$B36,Ofertas!$B$2:$B$124),1),"") -> 2.7 | F36: =SUMIF(Ofertas!$P$2:$P$124,$B36,Ofertas!$L$2:$L$124) -> 0 | G36: =IFERROR(ROUND(AVERAGEIF(Ofertas!$P$2:$P$124,$B36,Ofertas!$S$2:$S$124),0),"") -> 115 | H36: =REPT("|",C36) -> ||| | J36: s_replica x0,40 + s_lucro x0,25 + s_saturacao x0,20 + s_ticket x0,15
B37: ia-ferramentas | C37: =COUNTIF(Ofertas!$P$2:$P$124,$B37) -> 3 | D37: =IFERROR(ROUND(AVERAGEIF(Ofertas!$P$2:$P$124,$B37,Ofertas!$D$2:$D$124),1),"") -> 3.7 | E37: =IFERROR(ROUND(AVERAGEIF(Ofertas!$P$2:$P$124,$B37,Ofertas!$B$2:$B$124),1),"") -> 3 | F37: =SUMIF(Ofertas!$P$2:$P$124,$B37,Ofertas!$L$2:$L$124) -> 0 | G37: =IFERROR(ROUND(AVERAGEIF(Ofertas!$P$2:$P$124,$B37,Ofertas!$S$2:$S$124),0),"") -> 38 | H37: =REPT("|",C37) -> |||
B38: educacao | C38: =COUNTIF(Ofertas!$P$2:$P$124,$B38) -> 3 | D38: =IFERROR(ROUND(AVERAGEIF(Ofertas!$P$2:$P$124,$B38,Ofertas!$D$2:$D$124),1),"") -> 3.6 | E38: =IFERROR(ROUND(AVERAGEIF(Ofertas!$P$2:$P$124,$B38,Ofertas!$B$2:$B$124),1),"") -> 0 | F38: =SUMIF(Ofertas!$P$2:$P$124,$B38,Ofertas!$L$2:$L$124) -> 0 | G38: =IFERROR(ROUND(AVERAGEIF(Ofertas!$P$2:$P$124,$B38,Ofertas!$S$2:$S$124),0),"") -> 26 | H38: =REPT("|",C38) -> ||| | J38: NOTA GERAL = Quente x0,45 + Escalavel x0,55
B39: concursos | C39: =COUNTIF(Ofertas!$P$2:$P$124,$B39) -> 3 | D39: =IFERROR(ROUND(AVERAGEIF(Ofertas!$P$2:$P$124,$B39,Ofertas!$D$2:$D$124),1),"") -> 3.4 | E39: =IFERROR(ROUND(AVERAGEIF(Ofertas!$P$2:$P$124,$B39,Ofertas!$B$2:$B$124),1),"") -> 0.3 | F39: =SUMIF(Ofertas!$P$2:$P$124,$B39,Ofertas!$L$2:$L$124) -> 0 | G39: =IFERROR(ROUND(AVERAGEIF(Ofertas!$P$2:$P$124,$B39,Ofertas!$S$2:$S$124),0),"") -> 38 | H39: =REPT("|",C39) -> ||| | J39: Potencial: Alta >= 7 | Media >= 5 | Baixa < 5
B40: servicos-empresariais | C40: =COUNTIF(Ofertas!$P$2:$P$124,$B40) -> 2 | D40: =IFERROR(ROUND(AVERAGEIF(Ofertas!$P$2:$P$124,$B40,Ofertas!$D$2:$D$124),1),"") -> 5.4 | E40: =IFERROR(ROUND(AVERAGEIF(Ofertas!$P$2:$P$124,$B40,Ofertas!$B$2:$B$124),1),"") -> 6.3 | F40: =SUMIF(Ofertas!$P$2:$P$124,$B40,Ofertas!$L$2:$L$124) -> 0 | G40: =IFERROR(ROUND(AVERAGEIF(Ofertas!$P$2:$P$124,$B40,Ofertas!$S$2:$S$124),0),"") -> 0 | H40: =REPT("|",C40) -> ||
B41: artesanato-e-pdf | C41: =COUNTIF(Ofertas!$P$2:$P$124,$B41) -> 2 | D41: =IFERROR(ROUND(AVERAGEIF(Ofertas!$P$2:$P$124,$B41,Ofertas!$D$2:$D$124),1),"") -> 4.8 | E41: =IFERROR(ROUND(AVERAGEIF(Ofertas!$P$2:$P$124,$B41,Ofertas!$B$2:$B$124),1),"") -> 1.8 | F41: =SUMIF(Ofertas!$P$2:$P$124,$B41,Ofertas!$L$2:$L$124) -> 0 | G41: =IFERROR(ROUND(AVERAGEIF(Ofertas!$P$2:$P$124,$B41,Ofertas!$S$2:$S$124),0),"") -> 28 | H41: =REPT("|",C41) -> || | J41: Linha roxa na aba Ofertas = mesma pagina de destino que outra oferta.
B42: espionagem-rastreamento | C42: =COUNTIF(Ofertas!$P$2:$P$124,$B42) -> 2 | D42: =IFERROR(ROUND(AVERAGEIF(Ofertas!$P$2:$P$124,$B42,Ofertas!$D$2:$D$124),1),"") -> 3.6 | E42: =IFERROR(ROUND(AVERAGEIF(Ofertas!$P$2:$P$124,$B42,Ofertas!$B$2:$B$124),1),"") -> 1.8 | F42: =SUMIF(Ofertas!$P$2:$P$124,$B42,Ofertas!$L$2:$L$124) -> 0 | G42: =IFERROR(ROUND(AVERAGEIF(Ofertas!$P$2:$P$124,$B42,Ofertas!$S$2:$S$124),0),"") -> 86 | H42: =REPT("|",C42) -> ||
B43: streaming-e-acesso | C43: =COUNTIF(Ofertas!$P$2:$P$124,$B43) -> 2 | D43: =IFERROR(ROUND(AVERAGEIF(Ofertas!$P$2:$P$124,$B43,Ofertas!$D$2:$D$124),1),"") -> 3.3 | E43: =IFERROR(ROUND(AVERAGEIF(Ofertas!$P$2:$P$124,$B43,Ofertas!$B$2:$B$124),1),"") -> 1.8 | F43: =SUMIF(Ofertas!$P$2:$P$124,$B43,Ofertas!$L$2:$L$124) -> 0 | G43: =IFERROR(ROUND(AVERAGEIF(Ofertas!$P$2:$P$124,$B43,Ofertas!$S$2:$S$124),0),"") -> 20 | H43: =REPT("|",C43) -> ||
B44: marketing-digital | C44: =COUNTIF(Ofertas!$P$2:$P$124,$B44) -> 2 | D44: =IFERROR(ROUND(AVERAGEIF(Ofertas!$P$2:$P$124,$B44,Ofertas!$D$2:$D$124),1),"") -> 3.8 | E44: =IFERROR(ROUND(AVERAGEIF(Ofertas!$P$2:$P$124,$B44,Ofertas!$B$2:$B$124),1),"") -> 1.5 | F44: =SUMIF(Ofertas!$P$2:$P$124,$B44,Ofertas!$L$2:$L$124) -> 0 | G44: =IFERROR(ROUND(AVERAGEIF(Ofertas!$P$2:$P$124,$B44,Ofertas!$S$2:$S$124),0),"") -> 180 | H44: =REPT("|",C44) -> ||
B45: lives-interativas | C45: =COUNTIF(Ofertas!$P$2:$P$124,$B45) -> 2 | D45: =IFERROR(ROUND(AVERAGEIF(Ofertas!$P$2:$P$124,$B45,Ofertas!$D$2:$D$124),1),"") -> 3.3 | E45: =IFERROR(ROUND(AVERAGEIF(Ofertas!$P$2:$P$124,$B45,Ofertas!$B$2:$B$124),1),"") -> 1.5 | F45: =SUMIF(Ofertas!$P$2:$P$124,$B45,Ofertas!$L$2:$L$124) -> 0 | G45: =IFERROR(ROUND(AVERAGEIF(Ofertas!$P$2:$P$124,$B45,Ofertas!$S$2:$S$124),0),"") -> 75 | H45: =REPT("|",C45) -> ||
B46: ferramentas-ia | C46: =COUNTIF(Ofertas!$P$2:$P$124,$B46) -> 2 | D46: =IFERROR(ROUND(AVERAGEIF(Ofertas!$P$2:$P$124,$B46,Ofertas!$D$2:$D$124),1),"") -> 3.3 | E46: =IFERROR(ROUND(AVERAGEIF(Ofertas!$P$2:$P$124,$B46,Ofertas!$B$2:$B$124),1),"") -> 0.5 | F46: =SUMIF(Ofertas!$P$2:$P$124,$B46,Ofertas!$L$2:$L$124) -> 0 | G46: =IFERROR(ROUND(AVERAGEIF(Ofertas!$P$2:$P$124,$B46,Ofertas!$S$2:$S$124),0),"") -> 74 | H46: =REPT("|",C46) -> ||
B47: emagrecimento | C47: =COUNTIF(Ofertas!$P$2:$P$124,$B47) -> 2 | D47: =IFERROR(ROUND(AVERAGEIF(Ofertas!$P$2:$P$124,$B47,Ofertas!$D$2:$D$124),1),"") -> 2.9 | E47: =IFERROR(ROUND(AVERAGEIF(Ofertas!$P$2:$P$124,$B47,Ofertas!$B$2:$B$124),1),"") -> 0.5 | F47: =SUMIF(Ofertas!$P$2:$P$124,$B47,Ofertas!$L$2:$L$124) -> 0 | G47: =IFERROR(ROUND(AVERAGEIF(Ofertas!$P$2:$P$124,$B47,Ofertas!$S$2:$S$124),0),"") -> 53 | H47: =REPT("|",C47) -> ||
...

Sheet Ofertas
A1: Nome da oferta | B1: Quente (0-10) | C1: Escalavel (0-10) | D1: Nota geral | E1: Possibilidade de escala | F1: Grupo (mesmo destino) | G1: Ofertas no destino | H1: Cluster (mesma oferta/angulo) | I1: Ofertas no cluster | J1: Pagina de vendas | K1: Criativo / Biblioteca de Anuncios | L1: Criativos ativos | M1: Dias no ar | N1: Status | O1: Veredito | P1: Nicho | Q1: Sub-nicho | R1: Ticket frente (R$) | S1: Ticket medio est. (R$) | T1: Margem est. | U1: Checkout | V1: Reclamacoes RA | W1: Rodadas vista | X1: Visto primeiro | Y1: Visto ultimo | Z1: Entrega | AA1: Recorrencia | AB1: Tipo | AC1: s_ticket | AD1: s_lucro | AE1: s_replica | AF1: s_saturacao | AG1: Anunciante | AH1: Resumo
A2: Danca dos Noivos Online | B2: =MIN(10, IF(N2="ativa",5,IF(N2="nova",4,IF(N2="esfriando",2,0)))+IF(L2>=9,3,IF(L2>=3,2,IF(L2>=1,1,0)))+IF(M2>=60,1.5,IF(M2>=30,1,IF(M2>=14,0.5,0)))+IF(V2>=50,1.5,IF(V2>=10,1,IF(V2>=1,0.5,0)))+IF(W2>=4,0.5,0)) -> 8.5 | C2: =ROUND(AC2*0.15+AD2*0.25+AE2*0.4+AF2*0.2,1) -> 6.7 | D2: =ROUND(B2*0.45+C2*0.55,1) -> 7.5 | E2: =IF(D2>=7,"Alta",IF(D2>=5,"Media","Baixa")) -> Alta | F2: dancadosnoivosonline.com | G2: 1 | H2: danca-dos-noivos | I2: 1 | J2: abrir pagina | K2: anuncio 9 criativo(s) | L2: 9 | M2: 509 | N2: nova | O2: observar | P2: danca | Q2: danca-dos-noivos | R2: 97 | S2: 150 | T2: 0.85 | U2: hotmart | V2: 0 | W2: 1 | X2: 2026-09-06 | Y2: 2026-09-06 | Z2: curso | AA2: nao | AB2: Oferta | AC2: 9 | AD2: 10 | AE2: 3 | AF2: 8 | AG2: Danca dos Noivos | AH2: # Danca dos Noivos Online
A3: +150 Bonecas de Papel — Maria Criativa | B3: =MIN(10, IF(N3="ativa",5,IF(N3="nova",4,IF(N3="esfriando",2,0)))+IF(L3>=9,3,IF(L3>=3,2,IF(L3>=1,1,0)))+IF(M3>=60,1.5,IF(M3>=30,1,IF(M3>=14,0.5,0)))+IF(V3>=50,1.5,IF(V3>=10,1,IF(V3>=1,0.5,0)))+IF(W3>=4,0.5,0)) -> 8 | C3: =ROUND(AC3*0.15+AD3*0.25+AE3*0.4+AF3*0.2,1) -> 6.9 | D3: =ROUND(B3*0.45+C3*0.55,1) -> 7.4 | E3: =IF(D3>=7,"Alta",IF(D3>=5,"Media","Baixa")) -> Alta | F3: bonecasdepapel28.lovable.app | G3: 1 | H3: imprimivel-brincadeira | I3: 4 | J3: abrir pagina | K3: buscar na biblioteca | L3: 9 | M3: 54 | N3: nova | O3: observar | P3: comportamento-infantil | Q3: imprimivel-brincadeira | R3: 17.9 | S3: 24 | T3: 0.9 | U3: kirvano | V3: 0 | W3: 1 | X3: 2026-08-31 | Y3: 2026-08-31 | Z3: ebook | AA3: nao | AB3: Oferta | AC3: 3 | AD3: 8 | AE3: 10 | AF3: 2 | AH3: # +150 Bonecas de Papel — Maria Criativa
A4: Retrato da Alma Gemea | B4: =MIN(10, IF(N4="ativa",5,IF(N4="nova",4,IF(N4="esfriando",2,0)))+IF(L4>=9,3,IF(L4>=3,2,IF(L4>=1,1,0)))+IF(M4>=60,1.5,IF(M4>=30,1,IF(M4>=14,0.5,0)))+IF(V4>=50,1.5,IF(V4>=10,1,IF(V4>=1,0.5,0)))+IF(W4>=4,0.5,0)) -> 8 | C4: =ROUND(AC4*0.15+AD4*0.25+AE4*0.4+AF4*0.2,1) -> 6.5 | D4: =ROUND(B4*0.45+C4*0.55,1) -> 7.2 | E4: =IF(D4>=7,"Alta",IF(D4>=5,"Media","Baixa")) -> Alta | F4: alldigital.fun | G4: 1 | H4: retrato-alma-gemea | I4: 3 | J4: abrir pagina | K4: buscar na biblioteca | L4: 0 | M4: 1826 | N4: ativa | O4: observar | P4: esoterico | Q4: retrato-alma-gemea | R4: 29 | S4: 45 | T4: 0.97 | U4: kirvano | V4: 206 | W4: 2 | X4: 2026-08-30 | Y4: 2026-08-31 | Z4: servico-digital | AA4: nao | AB4: Oferta | AC4: 3 | AD4: 8 | AE4: 9 | AF4: 2 | AH4: # Retrato da Alma Gemea
A5: Colecao Completa de Caligrafia 1o ao 6o ano — 380 atividades | B5: =MIN(10, IF(N5="ativa",5,IF(N5="nova",4,IF(N5="esfriando",2,0)))+IF(L5>=9,3,IF(L5>=3,2,IF(L5>=1,1,0)))+IF(M5>=60,1.5,IF(M5>=30,1,IF(M5>=14,0.5,0)))+IF(V5>=50,1.5,IF(V5>=10,1,IF(V5>=1,0.5,0)))+IF(W5>=4,0.5,0)) -> 7.5 | C5: =ROUND(AC5*0.15+AD5*0.25+AE5*0.4+AF5*0.2,1) -> 6.8 | D5: =ROUND(B5*0.45+C5*0.55,1) -> 7.1 | E5: =IF(D5>=7,"Alta",IF(D5>=5,"Media","Baixa")) -> Alta | F5: atividade-cursiva.netlify.app | G5: 1 | H5: caligrafia | I5: 4 | J5: abrir pagina | K5: buscar na biblioteca | L5: 8 | M5: 123 | N5: nova | O5: replicar | P5: material-pedagogico | Q5: caligrafia | R5: 12 | S5: 12 | T5: 0.9 | U5: cakto | V5: 0 | W5: 1 | X5: 2026-08-31 | Y5: 2026-08-31 | Z5: ebook | AA5: nao | AB5: Oferta | AC5: 2 | AD5: 9 | AE5: 9 | AF5: 3 | AH5: # Colecao Completa de Caligrafia — 380 atividades
A6: Little Genius — Kit de 235+ atividades educativas | B6: =MIN(10, IF(N6="ativa",5,IF(N6="nova",4,IF(N6="esfriando",2,0)))+IF(L6>=9,3,IF(L6>=3,2,IF(L6>=1,1,0)))+IF(M6>=60,1.5,IF(M6>=30,1,IF(M6>=14,0.5,0)))+IF(V6>=50,1.5,IF(V6>=10,1,IF(V6>=1,0.5,0)))+IF(W6>=4,0.5,0)) -> 6.5 | C6: =ROUND(AC6*0.15+AD6*0.25+AE6*0.4+AF6*0.2,1) -> 7.5 | D6: =ROUND(B6*0.45+C6*0.55,1) -> 7.1 | E6: =IF(D6>=7,"Alta",IF(D6>=5,"Media","Baixa")) -> Alta | F6: thelittlegenius.com.br | G6: 1 | H6: estimulacao-cognitiva | I6: 1 | J6: abrir pagina | K6: buscar na biblioteca | L6: 1 | M6: 76 | N6: nova | O6: observar | P6: material-pedagogico | Q6: estimulacao-cognitiva | R6: 162 | S6: 162 | T6: 0.85 | U6: kiwify | V6: 0 | W6: 1 | X6: 2026-08-31 | Y6: 2026-08-31 | Z6: ebook | AA6: nao | AB6: Oferta | AC6: 10 | AD6: 7 | AE6: 7 | AF6: 7 | AH6: # Little Genius — 235 atividades a R$ 162
A7: Kit Grafismo Fonetico — Leitura Facil | B7: =MIN(10, IF(N7="ativa",5,IF(N7="nova",4,IF(N7="esfriando",2,0)))+IF(L7>=9,3,IF(L7>=3,2,IF(L7>=1,1,0)))+IF(M7>=60,1.5,IF(M7>=30,1,IF(M7>=14,0.5,0)))+IF(V7>=50,1.5,IF(V7>=10,1,IF(V7>=1,0.5,0)))+IF(W7>=4,0.5,0)) -> 8 | C7: =ROUND(AC7*0.15+AD7*0.25+AE7*0.4+AF7*0.2,1) -> 6.1 | D7: =ROUND(B7*0.45+C7*0.55,1) -> 7 | E7: =IF(D7>=7,"Alta",IF(D7>=5,"Media","Baixa")) -> Alta | F7: busca: grafismo fonetico | G7: 1 | H7: alfabetizacao | I7: 4 | J7: — | K7: buscar na biblioteca | L7: 10 | M7: 39 | N7: nova | O7: observar | P7: material-pedagogico | Q7: alfabetizacao | R7: 20 | S7: 20 | T7: 0.9 | U7: whatsapp | V7: 0 | W7: 1 | X7: 2026-08-31 | Y7: 2026-08-31 | Z7: ebook | AA7: nao | AB7: Oferta | AC7: 2 | AD7: 7 | AE7: 8 | AF7: 4 | AH7: # Kit Grafismo Fonetico — venda por conversa, 10 criativos
A8: Missa em Atividades — kit catolico infantil imprimivel | B8: =MIN(10, IF(N8="ativa",5,IF(N8="nova",4,IF(N8="esfriando",2,0)))+IF(L8>=9,3,IF(L8>=3,2,IF(L8>=1,1,0)))+IF(M8>=60,1.5,IF(M8>=30,1,IF(M8>=14,0.5,0)))+IF(V8>=50,1.5,IF(V8>=10,1,IF(V8>=1,0.5,0)))+IF(W8>=4,0.5,0)) -> 7 | C8: =ROUND(AC8*0.15+AD8*0.25+AE8*0.4+AF8*0.2,1) -> 6.7 | D8: =ROUND(B8*0.45+C8*0.55,1) -> 6.8 | E8: =IF(D8>=7,"Alta",IF(D8>=5,"Media","Baixa")) -> Media | F8: busca: missa em atividades | G8: 1 | H8: catequese-infantil | I8: 1 | J8: — | K8: buscar na biblioteca | L8: 3 | M8: 35 | N8: nova | O8: replicar | P8: comportamento-infantil | Q8: catequese-infantil | R8: 0 | S8: 0 | T8: 0.9 | U8: desconhecido | V8: 0 | W8: 1 | X8: 2026-08-31 | Y8: 2026-08-31 | Z8: ebook | AA8: nao | AB8: Oferta | AC8: 0 | AD8: 5 | AE8: 9 | AF8: 9 | AH8: # Missa em Atividades — o cruzamento mais vazio do vault
A9: Cantigas da Bailarina — repertorio pronto para Baby Class | B9: =MIN(10, IF(N9="ativa",5,IF(N9="nova",4,IF(N9="esfriando",2,0)))+IF(L9>=9,3,IF(L9>=3,2,IF(L9>=1,1,0)))+IF(M9>=60,1.5,IF(M9>=30,1,IF(M9>=14,0.5,0)))+IF(V9>=50,1.5,IF(V9>=10,1,IF(V9>=1,0.5,0)))+IF(W9>=4,0.5,0)) -> 7 | C9: =ROUND(AC9*0.15+AD9*0.25+AE9*0.4+AF9*0.2,1) -> 6.2 | D9: =ROUND(B9*0.45+C9*0.55,1) -> 6.6 | E9: =IF(D9>=7,"Alta",IF(D9>=5,"Media","Baixa")) -> Media | F9: ballerinalab.com.br | G9: 1 | H9: material-para-professora-de-ballet | I9: 2 | J9: abrir pagina | K9: anuncio 11 criativo(s) | L9: 11 | M9: 9 | N9: nova | O9: observar | P9: danca | Q9: material-para-professora-de-ballet | R9: 19.9 | S9: 35 | T9: 0.9 | U9: ggcheckout | V9: 0 | W9: 1 | X9: 2026-09-06 | Y9: 2026-09-06 | Z9: ebook | AA9: nao | AB9: Oferta | AC9: 5 | AD9: 4 | AE9: 8 | AF9: 6 | AG9: Ballerina Lab | AH9: # Cantigas da Bailarina — Ballerina Lab
A10: Angulo — material pronto para quem ENSINA danca | B10: =MIN(10, IF(N10="ativa",5,IF(N10="nova",4,IF(N10="esfriando",2,0)))+IF(L10>=9,3,IF(L10>=3,2,IF(L10>=1,1,0)))+IF(M10>=60,1.5,IF(M10>=30,1,IF(M10>=14,0.5,0)))+IF(V10>=50,1.5,IF(V10>=10,1,IF(V10>=1,0.5,0)))+IF(W10>=4,0.5,0)) -> 7 | C10: =ROUND(AC10*0.15+AD10*0.25+AE10*0.4+AF10*0.2,1) -> 6.2 | D10: =ROUND(B10*0.45+C10*0.55,1) -> 6.6 | E10: =IF(D10>=7,"Alta",IF(D10>=5,"Media","Baixa")) -> Media | F10: busca: coreografias prontas | G10: 1 | H10: material-para-professor | I10: 1 | J10: — | K10: buscar na biblioteca | L10: 19 | M10: 10 | N10: nova | O10: replicar | P10: danca | Q10: material-para-professor | R10: 19.9 | S10: 30 | T10: 0.92 | U10: desconhecido | V10: 0 | W10: 1 | X10: 2026-09-06 | Y10: 2026-09-06 | Z10: ebook | AA10: nao | AB10: Angulo | AC10: 4 | AD10: 4 | AE10: 9 | AF10: 5 | AH10: # Angulo — material pronto para quem ENSINA danca
A11: Casinha dos Sonhos — casinha de papel imprimivel | B11: =MIN(10, IF(N11="ativa",5,IF(N11="nova",4,IF(N11="esfriando",2,0)))+IF(L11>=9,3,IF(L11>=3,2,IF(L11>=1,1,0)))+IF(M11>=60,1.5,IF(M11>=30,1,IF(M11>=14,0.5,0)))+IF(V11>=50,1.5,IF(V11>=10,1,IF(V11>=1,0.5,0)))+IF(W11>=4,0.5,0)) -> 6 | C11: =ROUND(AC11*0.15+AD11*0.25+AE11*0.4+AF11*0.2,1) -> 6.9 | D11: =ROUND(B11*0.45+C11*0.55,1) -> 6.5 | E11: =IF(D11>=7,"Alta",IF(D11>=5,"Media","Baixa")) -> Media | F11: casinhadossonhos.com.br | G11: 1 | H11: imprimivel-brincadeira | I11: 4 | J11: abrir pagina | K11: buscar na biblioteca | L11: 2 | M11: 42 | N11: nova | O11: observar | P11: comportamento-infantil | Q11: imprimivel-brincadeira | R11: 10 | S11: 10 | T11: 0.9 | U11: desconhecido | V11: 0 | W11: 1 | X11: 2026-08-31 | Y11: 2026-08-31 | Z11: ebook | AA11: nao | AB11: Oferta | AC11: 1 | AD11: 6 | AE11: 10 | AF11: 6 | AG11: Prof.a Juliana Gamon | AH11: # Casinha dos Sonhos — R$ 10, 42 dias no ar
A12: Kit de Alfabetizacao Alfa Kids — 2.750 atividades | B12: =MIN(10, IF(N12="ativa",5,IF(N12="nova",4,IF(N12="esfriando",2,0)))+IF(L12>=9,3,IF(L12>=3,2,IF(L12>=1,1,0)))+IF(M12>=60,1.5,IF(M12>=30,1,IF(M12>=14,0.5,0)))+IF(V12>=50,1.5,IF(V12>=10,1,IF(V12>=1,0.5,0)))+IF(W12>=4,0.5,0)) -> 6.5 | C12: =ROUND(AC12*0.15+AD12*0.25+AE12*0.4+AF12*0.2,1) -> 6.1 | D12: =ROUND(B12*0.45+C12*0.55,1) -> 6.3 | E12: =IF(D12>=7,"Alta",IF(D12>=5,"Media","Baixa")) -> Media | F12: busca: alfa kids | G12: 1 | H12: alfabetizacao | I12: 4 | J12: — | K12: buscar na biblioteca | L12: 2 | M12: 107 | N12: nova | O12: observar | P12: material-pedagogico | Q12: alfabetizacao | R12: 0 | S12: 0 | T12: 0.9 | U12: desconhecido | V12: 0 | W12: 1 | X12: 2026-08-31 | Y12: 2026-08-31 | Z12: ebook | AA12: nao | AB12: Oferta | AC12: 0 | AD12: 9 | AE12: 8 | AF12: 3 | AH12: # Turminha Alfa Kids — 107 dias no ar
A13: Clube da Pedagogia — kit 3.000+ atividades BNCC | B13: =MIN(10, IF(N13="ativa",5,IF(N13="nova",4,IF(N13="esfriando",2,0)))+IF(L13>=9,3,IF(L13>=3,2,IF(L13>=1,1,0)))+IF(M13>=60,1.5,IF(M13>=30,1,IF(M13>=14,0.5,0)))+IF(V13>=50,1.5,IF(V13>=10,1,IF(V13>=1,0.5,0)))+IF(W13>=4,0.5,0)) -> 6.5 | C13: =ROUND(AC13*0.15+AD13*0.25+AE13*0.4+AF13*0.2,1) -> 6.1 | D13: =ROUND(B13*0.45+C13*0.55,1) -> 6.3 | E13: =IF(D13>=7,"Alta",IF(D13>=5,"Media","Baixa")) -> Media | F13: clubedapedagogia.com | G13: 1 | H13: acervo-professora | I13: 2 | J13: abrir pagina | K13: buscar na biblioteca | L13: 1 | M13: 74 | N13: nova | O13: replicar | P13: material-pedagogico | Q13: acervo-professora | R13: 20 | S13: 35 | T13: 0.9 | U13: ggcheckout | V13: 0 | W13: 1 | X13: 2026-08-31 | Y13: 2026-08-31 | Z13: ebook | AA13: nao | AB13: Oferta | AC13: 5 | AD13: 7 | AE13: 7 | AF13: 4 | AH13: # Clube da Pedagogia — a escada que o cluster infantil nao tem
A14: Combo 10 Cursos de Danca do Ventre — Patricia Cavalcante | B14: =MIN(10, IF(N14="ativa",5,IF(N14="nova",4,IF(N14="esfriando",2,0)))+IF(L14>=9,3,IF(L14>=3,2,IF(L14>=1,1,0)))+IF(M14>=60,1.5,IF(M14>=30,1,IF(M14>=14,0.5,0)))+IF(V14>=50,1.5,IF(V14>=10,1,IF(V14>=1,0.5,0)))+IF(W14>=4,0.5,0)) -> 6.5 | C14: =ROUND(AC14*0.15+AD14*0.25+AE14*0.4+AF14*0.2,1) -> 6 | D14: =ROUND(B14*0.45+C14*0.55,1) -> 6.2 | E14: =IF(D14>=7,"Alta",IF(D14>=5,"Media","Baixa")) -> Media | F14: patriciacavalcante.com.br | G14: 1 | H14: danca-do-ventre | I14: 2 | J14: abrir pagina | K14: anuncio 2 criativo(s) | L14: 2 | M14: 584 | N14: nova | O14: descartar | P14: danca | Q14: danca-do-ventre | R14: 247 | S14: 247 | T14: 0.85 | U14: hotmart | V14: 0 | W14: 1 | X14: 2026-09-06 | Y14: 2026-09-06 | Z14: curso | AA14: nao | AB14: Oferta | AC14: 10 | AD14: 10 | AE14: 2 | AF14: 6 | AG14: Patricia Cavalcante | AH14: # Combo 10 Cursos de Danca do Ventre
A15: Portal Shakti Club — bellydance e tribal fusion | B15: =MIN(10, IF(N15="ativa",5,IF(N15="nova",4,IF(N15="esfriando",2,0)))+IF(L15>=9,3,IF(L15>=3,2,IF(L15>=1,1,0)))+IF(M15>=60,1.5,IF(M15>=30,1,IF(M15>=14,0.5,0)))+IF(V15>=50,1.5,IF(V15>=10,1,IF(V15>=1,0.5,0)))+IF(W15>=4,0.5,0)) -> 7.5 | C15: =ROUND(AC15*0.15+AD15*0.25+AE15*0.4+AF15*0.2,1) -> 5.3 | D15: =ROUND(B15*0.45+C15*0.55,1) -> 6.3 | E15: =IF(D15>=7,"Alta",IF(D15>=5,"Media","Baixa")) -> Media | F15: shaktistudioonline.com | G15: 1 | H15: danca-do-ventre | I15: 2 | J15: abrir pagina | K15: anuncio 3 criativo(s) | L15: 3 | M15: 81 | N15: nova | O15: descartar | P15: danca | Q15: danca-do-ventre | R15: 97 | S15: 210 | T15: 0.85 | U15: kiwify | V15: 0 | W15: 1 | X15: 2026-09-06 | Y15: 2026-09-06 | Z15: curso, comunidade | AA15: sim | AB15: Oferta | AC15: 10 | AD15: 7 | AE15: 2 | AF15: 6 | AG15: Luma Shakti Studio Online | AH15: # Portal Shakti Club
A16: Kit Mundinho de Papel | B16: =MIN(10, IF(N16="ativa",5,IF(N16="nova",4,IF(N16="esfriando",2,0)))+IF(L16>=9,3,IF(L16>=3,2,IF(L16>=1,1,0)))+IF(M16>=60,1.5,IF(M16>=30,1,IF(M16>=14,0.5,0)))+IF(V16>=50,1.5,IF(V16>=10,1,IF(V16>=1,0.5,0)))+IF(W16>=4,0.5,0)) -> 6 | C16: =ROUND(AC16*0.15+AD16*0.25+AE16*0.4+AF16*0.2,1) -> 6.1 | D16: =ROUND(B16*0.45+C16*0.55,1) -> 6.1 | E16: =IF(D16>=7,"Alta",IF(D16>=5,"Media","Baixa")) -> Media | F16: bibliotecainterativa.com | G16: 1 | H16: imprimivel-brincadeira | I16: 4 | J16: abrir pagina | K16: buscar na biblioteca | L16: 1 | M16: 54 | N16: nova | O16: observar | P16: comportamento-infantil | Q16: imprimivel-brincadeira | R16: 10 | S16: 10 | T16: 0.9 | U16: desconhecido | V16: 0 | W16: 1 | X16: 2026-08-31 | Y16: 2026-08-31 | Z16: ebook | AA16: nao | AB16: Oferta | AC16: 1 | AD16: 6 | AE16: 10 | AF16: 2 | AH16: # Kit Mundinho de Papel — R$ 10
A17: Tutu da Ju — assinatura de ballet classico online | B17: =MIN(10, IF(N17="ativa",5,IF(N17="nova",4,IF(N17="esfriando",2,0)))+IF(L17>=9,3,IF(L17>=3,2,IF(L17>=1,1,0)))+IF(M17>=60,1.5,IF(M17>=30,1,IF(M17>=14,0.5,0)))+IF(V17>=50,1.5,IF(V17>=10,1,IF(V17>=1,0.5,0)))+IF(W17>=4,0.5,0)) -> 6.5 | C17: =ROUND(AC17*0.15+AD17*0.25+AE17*0.4+AF17*0.2,1) -> 5.7 | D17: =ROUND(B17*0.45+C17*0.55,1) -> 6.1 | E17: =IF(D17>=7,"Alta",IF(D17>=5,"Media","Baixa")) -> Media | F17: conteudos.tutudaju.com | G17: 1 | H17: ballet-adulto | I17: 1 | J17: abrir pagina | K17: anuncio 1 criativo(s) | L17: 1 | M17: 137 | N17: nova | O17: observar | P17: danca | Q17: ballet-adulto | R17: 50 | S17: 150 | T17: 0.85 | U17: hotmart | V17: 0 | W17: 1 | X17: 2026-09-06 | Y17: 2026-09-06 | Z17: curso, comunidade | AA17: sim | AB17: Oferta | AC17: 9 | AD17: 7 | AE17: 3 | AF17: 7 | AG17: Tutu da Ju | AH17: # Tutu da Ju — assinatura
A18: Cursos Gratis Online | B18: =MIN(10, IF(N18="ativa",5,IF(N18="nova",4,IF(N18="esfriando",2,0)))+IF(L18>=9,3,IF(L18>=3,2,IF(L18>=1,1,0)))+IF(M18>=60,1.5,IF(M18>=30,1,IF(M18>=14,0.5,0)))+IF(V18>=50,1.5,IF(V18>=10,1,IF(V18>=1,0.5,0)))+IF(W18>=4,0.5,0)) -> 7 | C18: =ROUND(AC18*0.15+AD18*0.25+AE18*0.4+AF18*0.2,1) -> 5.4 | D18: =ROUND(B18*0.45+C18*0.55,1) -> 6.1 | E18: =IF(D18>=7,"Alta",IF(D18>=5,"Media","Baixa")) -> Media | F18: cursosgratisonline.com.br | G18: 1 | H18: taxa-para-liberar-certificado | I18: 4 | J18: abrir pagina | K18: buscar na biblioteca | L18: 0 | M18: 210 | N18: nova | O18: observar | P18: certificacao | Q18: taxa-para-liberar-certificado | R18: 79.9 | S18: 90 | T18: 0.9 | U18: desconhecido | V18: 114 | W18: 1 | X18: 2026-08-30 | Y18: 2026-08-30 | Z18: curso | AA18: nao | AB18: Oferta | AC18: 7 | AD18: 7 | AE18: 5 | AF18: 3 | AH18: # Cursos Gratis Online
A19: Google Captcha (TW Empreendimentos Digitais) | B19: =MIN(10, IF(N19="ativa",5,IF(N19="nova",4,IF(N19="esfriando",2,0)))+IF(L19>=9,3,IF(L19>=3,2,IF(L19>=1,1,0)))+IF(M19>=60,1.5,IF(M19>=30,1,IF(M19>=14,0.5,0)))+IF(V19>=50,1.5,IF(V19>=10,1,IF(V19>=1,0.5,0)))+IF(W19>=4,0.5,0)) -> 7.5 | C19: =ROUND(AC19*0.15+AD19*0.25+AE19*0.4+AF19*0.2,1) -> 4.8 | D19: =ROUND(B19*0.45+C19*0.55,1) -> 6 | E19: =IF(D19>=7,"Alta",IF(D19>=5,"Media","Baixa")) -> Media | F19: busca: Google Captcha ganhar dinheiro | G19: 1 | H19: taxa-para-liberar | I19: 3 | J19: — | K19: buscar na biblioteca | L19: 0 | M19: 61 | N19: ativa | O19: observar | P19: ganhar-dinheiro | Q19: taxa-para-liberar | R19: 50 | S19: 150 | T19: 0.95 | U19: perfectpay | V19: 39 | W19: 2 | X19: 2026-08-28 | Y19: 2026-08-29 | Z19: app | AA19: nao | AB19: Oferta | AC19: 9 | AD19: 8 | AE19: 2 | AF19: 3 | AH19: # Google Captcha (TW Empreendimentos Digitais)
A20: Alfabetinho — pacotes de atividades imprimiveis | B20: =MIN(10, IF(N20="ativa",5,IF(N20="nova",4,IF(N20="esfriando",2,0)))+IF(L20>=9,3,IF(L20>=3,2,IF(L20>=1,1,0)))+IF(M20>=60,1.5,IF(M20>=30,1,IF(M20>=14,0.5,0)))+IF(V20>=50,1.5,IF(V20>=10,1,IF(V20>=1,0.5,0)))+IF(W20>=4,0.5,0)) -> 6.5 | C20: =ROUND(AC20*0.15+AD20*0.25+AE20*0.4+AF20*0.2,1) -> 5.4 | D20: =ROUND(B20*0.45+C20*0.55,1) -> 5.9 | E20: =IF(D20>=7,"Alta",IF(D20>=5,"Media","Baixa")) -> Media | F20: alfabetinho.com.br | G20: 1 | H20: alfabetizacao-e-educacao-especial | I20: 1 | J20: abrir pagina | K20: buscar na biblioteca | L20: 0 | M20: 0 | N20: ativa | O20: observar | P20: material-pedagogico | Q20: alfabetizacao-e-educacao-especial | R20: 0 | S20: 0 | T20: 0.85 | U20: desconhecido | V20: 177 | W20: 1 | X20: 2026-08-29 | Y20: 2026-08-29 | Z20: ebook, curso | AA20: nao | AB20: Oferta | AC20: 0 | AD20: 7 | AE20: 7 | AF20: 4 | AH20: # Alfabetinho — pacotes de atividades imprimiveis
A21: Licao Kids — loja de atividades imprimiveis | B21: =MIN(10, IF(N21="ativa",5,IF(N21="nova",4,IF(N21="esfriando",2,0)))+IF(L21>=9,3,IF(L21>=3,2,IF(L21>=1,1,0)))+IF(M21>=60,1.5,IF(M21>=30,1,IF(M21>=14,0.5,0)))+IF(V21>=50,1.5,IF(V21>=10,1,IF(V21>=1,0.5,0)))+IF(W21>=4,0.5,0)) -> 6 | C21: =ROUND(AC21*0.15+AD21*0.25+AE21*0.4+AF21*0.2,1) -> 5.8 | D21: =ROUND(B21*0.45+C21*0.55,1) -> 5.9 | E21: =IF(D21>=7,"Alta",IF(D21>=5,"Media","Baixa")) -> Media | F21: licaokids.com.br | G21: 1 | H21: acervo-professora | I21: 2 | J21: abrir pagina | K21: buscar na biblioteca | L21: 1 | M21: 50 | N21: nova | O21: observar | P21: material-pedagogico | Q21: acervo-professora | R21: 9.9 | S21: 25 | T21: 0.9 | U21: desconhecido | V21: 0 | W21: 1 | X21: 2026-08-31 | Y21: 2026-08-31 | Z21: ebook | AA21: nao | AB21: Oferta | AC21: 3 | AD21: 6 | AE21: 7 | AF21: 5 | AH21: # Licao Kids — loja, nao funil
A22: Caderno Completo de Caligrafia — +300 atividades | B22: =MIN(10, IF(N22="ativa",5,IF(N22="nova",4,IF(N22="esfriando",2,0)))+IF(L22>=9,3,IF(L22>=3,2,IF(L22>=1,1,0)))+IF(M22>=60,1.5,IF(M22>=30,1,IF(M22>=14,0.5,0)))+IF(V22>=50,1.5,IF(V22>=10,1,IF(V22>=1,0.5,0)))+IF(W22>=4,0.5,0)) -> 6 | C22: =ROUND(AC22*0.15+AD22*0.25+AE22*0.4+AF22*0.2,1) -> 5.9 | D22: =ROUND(B22*0.45+C22*0.55,1) -> 5.9 | E22: =IF(D22>=7,"Alta",IF(D22>=5,"Media","Baixa")) -> Media | F22: mundocriativobr.shop | G22: 1 | H22: caligrafia | I22: 4 | J22: abrir pagina | K22: buscar na biblioteca | L22: 1 | M22: 47 | N22: nova | O22: observar | P22: material-pedagogico | Q22: caligrafia | R22: 10 | S22: 10 | T22: 0.9 | U22: desconhecido | V22: 0 | W22: 1 | X22: 2026-08-31 | Y22: 2026-08-31 | Z22: ebook | AA22: nao | AB22: Oferta | AC22: 1 | AD22: 6 | AE22: 9 | AF22: 3 | AH22: # Mundo Criativo — +300 atividades de caligrafia a R$ 10
A23: Atelie Digital Pequenas Estilistas — Colecao 2027 | B23: =MIN(10, IF(N23="ativa",5,IF(N23="nova",4,IF(N23="esfriando",2,0)))+IF(L23>=9,3,IF(L23>=3,2,IF(L23>=1,1,0)))+IF(M23>=60,1.5,IF(M23>=30,1,IF(M23>=14,0.5,0)))+IF(V23>=50,1.5,IF(V23>=10,1,IF(V23>=1,0.5,0)))+IF(W23>=4,0.5,0)) -> 5.5 | C23: =ROUND(AC23*0.15+AD23*0.25+AE23*0.4+AF23*0.2,1) -> 6.2 | D23: =ROUND(B23*0.45+C23*0.55,1) -> 5.9 | E23: =IF(D23>=7,"Alta",IF(D23>=5,"Media","Baixa")) -> Media | F23: pequenasestilistas.com | G23: 1 | H23: moda-infantil | I23: 1 | J23: abrir pagina | K23: buscar na biblioteca | L23: 2 | M23: 19 | N23: nova | O23: observar | P23: comportamento-infantil | Q23: moda-infantil | R23: 27.9 | S23: 27.9 | T23: 0.9 | U23: hotmart | V23: 0 | W23: 1 | X23: 2026-08-31 | Y23: 2026-08-31 | Z23: ebook | AA23: nao | AB23: Oferta | AC23: 3 | AD23: 3 | AE23: 9 | AF23: 7 | AH23: # Pequenas Estilistas — o mesmo PDF por 2,3x o preco do vizinho
A24: Escada de taxas decrescentes no pos-compra (nome nao capturado) | B24: =MIN(10, IF(N24="ativa",5,IF(N24="nova",4,IF(N24="esfriando",2,0)))+IF(L24>=9,3,IF(L24>=3,2,IF(L24>=1,1,0)))+IF(M24>=60,1.5,IF(M24>=30,1,IF(M24>=14,0.5,0)))+IF(V24>=50,1.5,IF(V24>=10,1,IF(V24>=1,0.5,0)))+IF(W24>=4,0.5,0)) -> 5.5 | C24: =ROUND(AC24*0.15+AD24*0.25+AE24*0.4+AF24*0.2,1) -> 6.1 | D24: =ROUND(B24*0.45+C24*0.55,1) -> 5.8 | E24: =IF(D24>=7,"Alta",IF(D24>=5,"Media","Baixa")) -> Media | F24: busca: curso taxa de liberação | G24: 1 | H24: taxa-para-liberar | I24: 3 | J24: — | K24: buscar na biblioteca | L24: 0 | M24: 0 | N24: ativa | O24: observar | P24: mecanica-de-checkout | Q24: taxa-para-liberar | R24: 27.9 | S24: 46.7 | T24: 0.9 | U24: perfectpay | V24: 1 | W24: 3 | X24: 2026-08-27 | Y24: 2026-08-29 | Z24: curso | AA24: nao | AB24: Oferta | AC24: 5 | AD24: 3 | AE24: 8 | AF24: 7 | AH24: # Escada de taxas decrescentes no pos-compra (nome nao capturado)
A25: Dicionario em Movimento — 90 movimentos para ministracao | B25: =MIN(10, IF(N25="ativa",5,IF(N25="nova",4,IF(N25="esfriando",2,0)))+IF(L25>=9,3,IF(L25>=3,2,IF(L25>=1,1,0)))+IF(M25>=60,1.5,IF(M25>=30,1,IF(M25>=14,0.5,0)))+IF(V25>=50,1.5,IF(V25>=10,1,IF(V25>=1,0.5,0)))+IF(W25>=4,0.5,0)) -> 6 | C25: =ROUND(AC25*0.15+AD25*0.25+AE25*0.4+AF25*0.2,1) -> 5.6 | D25: =ROUND(B25*0.45+C25*0.55,1) -> 5.8 | E25: =IF(D25>=7,"Alta",IF(D25>=5,"Media","Baixa")) -> Media | F25: dicionarioemmovimento.site | G25: 1 | H25: danca-gospel-ministerio | I25: 3 | J25: abrir pagina | K25: anuncio 3 criativo(s) | L25: 3 | M25: 12 | N25: nova | O25: observar | P25: danca | Q25: danca-gospel-ministerio | R25: 67 | S25: 67 | T25: 0.88 | U25: onprofit | V25: 0 | W25: 1 | X25: 2026-09-06 | Y25: 2026-09-06 | Z25: ebook, curso | AA25: nao | AB25: Oferta | AC25: 7 | AD25: 3 | AE25: 7 | AF25: 5 | AG25: Escola de Danca Louvor na Terra | AH25: # Dicionario em Movimento
A26: Aerobico Ritmado — aula pronta com certificado de 50h | B26: =MIN(10, IF(N26="ativa",5,IF(N26="nova",4,IF(N26="esfriando",2,0)))+IF(L26>=9,3,IF(L26>=3,2,IF(L26>=1,1,0)))+IF(M26>=60,1.5,IF(M26>=30,1,IF(M26>=14,0.5,0)))+IF(V26>=50,1.5,IF(V26>=10,1,IF(V26>=1,0.5,0)))+IF(W26>=4,0.5,0)) -> 6 | C26: =ROUND(AC26*0.15+AD26*0.25+AE26*0.4+AF26*0.2,1) -> 5.7 | D26: =ROUND(B26*0.45+C26*0.55,1) -> 5.8 | E26: =IF(D26>=7,"Alta",IF(D26>=5,"Media","Baixa")) -> Media | F26: galeraindica.com.br | G26: 1 | H26: danca-para-professor-de-edfisica | I26: 1 | J26: abrir pagina | K26: anuncio 3 criativo(s) | L26: 3 | M26: 10 | N26: nova | O26: observar | P26: danca | Q26: danca-para-professor-de-edfisica | R26: 67 | S26: 67 | T26: 0.88 | U26: hotmart | V26: 0 | W26: 1 | X26: 2026-09-06 | Y26: 2026-09-06 | Z26: curso, ebook | AA26: nao | AB26: Oferta | AC26: 7 | AD26: 4 | AE26: 7 | AF26: 4 | AG26: Galera da EdFisica | AH26: # Aerobico Ritmado — Galera da EdFisica
A27: The Soulmate Sketcher | B27: =MIN(10, IF(N27="ativa",5,IF(N27="nova",4,IF(N27="esfriando",2,0)))+IF(L27>=9,3,IF(L27>=3,2,IF(L27>=1,1,0)))+IF(M27>=60,1.5,IF(M27>=30,1,IF(M27>=14,0.5,0)))+IF(V27>=50,1.5,IF(V27>=10,1,IF(V27>=1,0.5,0)))+IF(W27>=4,0.5,0)) -> 5 | C27: =ROUND(AC27*0.15+AD27*0.25+AE27*0.4+AF27*0.2,1) -> 6.5 | D27: =ROUND(B27*0.45+C27*0.55,1) -> 5.8 | E27: =IF(D27>=7,"Alta",IF(D27>=5,"Media","Baixa")) -> Media | F27: thesoulmatesketcher.com | G27: 1 | H27: retrato-alma-gemea | I27: 3 | J27: abrir pagina | K27: buscar na biblioteca | L27: 0 | M27: 0 | N27: ativa | O27: observar | P27: esoterico | Q27: retrato-alma-gemea | R27: 27 | S27: 27 | T27: 0.97 | U27: proprio | V27: 0 | W27: 1 | X27: 2026-08-30 | Y27: 2026-08-30 | Z27: servico-digital | AA27: nao | AB27: Oferta | AC27: 7 | AD27: 4 | AE27: 8 | AF27: 6 | AH27: # The Soulmate Sketcher
A28: Portal do MEI Brasil | B28: =MIN(10, IF(N28="ativa",5,IF(N28="nova",4,IF(N28="esfriando",2,0)))+IF(L28>=9,3,IF(L28>=3,2,IF(L28>=1,1,0)))+IF(M28>=60,1.5,IF(M28>=30,1,IF(M28>=14,0.5,0)))+IF(V28>=50,1.5,IF(V28>=10,1,IF(V28>=1,0.5,0)))+IF(W28>=4,0.5,0)) -> 7 | C28: =ROUND(AC28*0.15+AD28*0.25+AE28*0.4+AF28*0.2,1) -> 4.7 | D28: =ROUND(B28*0.45+C28*0.55,1) -> 5.7 | E28: =IF(D28>=7,"Alta",IF(D28>=5,"Media","Baixa")) -> Media | F28: busca: abrir mei online | G28: 1 | H28: taxa-sobre-servico-publico-gratuito | I28: 2 | J28: — | K28: buscar na biblioteca | L28: 0 | M28: 210 | N28: nova | O28: observar | P28: servicos-empresariais | Q28: taxa-sobre-servico-publico-gratuito | R28: 0 | S28: 0 | T28: 0.95 | U28: desconhecido | V28: 889 | W28: 1 | X28: 2026-08-30 | Y28: 2026-08-30 | Z28: ebook | AA28: nao | AB28: Oferta | AC28: 0 | AD28: 10 | AE28: 4 | AF28: 3 | AH28: # Portal do MEI Brasil
A29: Certificado Curso Online — curso gratis, certificado R$ 139,90 | B29: =MIN(10, IF(N29="ativa",5,IF(N29="nova",4,IF(N29="esfriando",2,0)))+IF(L29>=9,3,IF(L29>=3,2,IF(L29>=1,1,0)))+IF(M29>=60,1.5,IF(M29>=30,1,IF(M29>=14,0.5,0)))+IF(V29>=50,1.5,IF(V29>=10,1,IF(V29>=1,0.5,0)))+IF(W29>=4,0.5,0)) -> 6.5 | C29: =ROUND(AC29*0.15+AD29*0.25+AE29*0.4+AF29*0.2,1) -> 5.2 | D29: =ROUND(B29*0.45+C29*0.55,1) -> 5.8 | E29: =IF(D29>=7,"Alta",IF(D29>=5,"Media","Baixa")) -> Media | F29: certificadocursosonline.com | G29: 1 | H29: taxa-para-liberar-certificado | I29: 4 | J29: abrir pagina | K29: buscar na biblioteca | L29: 0 | M29: 0 | N29: ativa | O29: observar | P29: certificacao | Q29: taxa-para-liberar-certificado | R29: 139.9 | S29: 139.9 | T29: 0.95 | U29: desconhecido | V29: 58 | W29: 1 | X29: 2026-08-29 | Y29: 2026-08-29 | Z29: curso | AA29: nao | AB29: Oferta | AC29: 9 | AD29: 4 | AE29: 5 | AF29: 4 | AH29: # Certificado Curso Online — curso gratis, certificado R$ 139,90
A30: Kit Do Rabisco a Letra Bonita — Uiara Oliveira | B30: =MIN(10, IF(N30="ativa",5,IF(N30="nova",4,IF(N30="esfriando",2,0)))+IF(L30>=9,3,IF(L30>=3,2,IF(L30>=1,1,0)))+IF(M30>=60,1.5,IF(M30>=30,1,IF(M30>=14,0.5,0)))+IF(V30>=50,1.5,IF(V30>=10,1,IF(V30>=1,0.5,0)))+IF(W30>=4,0.5,0)) -> 6 | C30: =ROUND(AC30*0.15+AD30*0.25+AE30*0.4+AF30*0.2,1) -> 5.2 | D30: =ROUND(B30*0.45+C30*0.55,1) -> 5.6 | E30: =IF(D30>=7,"Alta",IF(D30>=5,"Media","Baixa")) -> Media | F30: busca: do rabisco a letra bonita | G30: 1 | H30: caligrafia | I30: 4 | J30: — | K30: buscar na biblioteca | L30: 1 | M30: 32 | N30: nova | O30: observar | P30: material-pedagogico | Q30: caligrafia | R30: 0 | S30: 0 | T30: 0.9 | U30: desconhecido | V30: 0 | W30: 1 | X30: 2026-08-31 | Y30: 2026-08-31 | Z30: ebook | AA30: nao | AB30: Oferta | AC30: 0 | AD30: 4 | AE30: 9 | AF30: 3 | AH30: # Do Rabisco a Letra Bonita
A31: 250 Dinamicas de Ballet Prontas para Professoras | B31: =MIN(10, IF(N31="ativa",5,IF(N31="nova",4,IF(N31="esfriando",2,0)))+IF(L31>=9,3,IF(L31>=3,2,IF(L31>=1,1,0)))+IF(M31>=60,1.5,IF(M31>=30,1,IF(M31>=14,0.5,0)))+IF(V31>=50,1.5,IF(V31>=10,1,IF(V31>=1,0.5,0)))+IF(W31>=4,0.5,0)) -> 5 | C31: =ROUND(AC31*0.15+AD31*0.25+AE31*0.4+AF31*0.2,1) -> 5.9 | D31: =ROUND(B31*0.45+C31*0.55,1) -> 5.5 | E31: =IF(D31>=7,"Alta",IF(D31>=5,"Media","Baixa")) -> Media | F31: dinamicadeballet.netlify.app | G31: 1 | H31: material-para-professora-de-ballet | I31: 2 | J31: abrir pagina | K31: anuncio 2 criativo(s) | L31: 2 | M31: 9 | N31: nova | O31: observar | P31: danca | Q31: material-para-professora-de-ballet | R31: 10 | S31: 15 | T31: 0.93 | U31: payt | V31: 0 | W31: 1 | X31: 2026-09-06 | Y31: 2026-09-06 | Z31: ebook | AA31: nao | AB31: Oferta | AC31: 2 | AD31: 3 | AE31: 9 | AF31: 6 | AG31: Material da Prof | AH31: # 250 Dinamicas de Ballet — Material da Prof
A32: Angulo - Quiz de 60s que gera o retrato | B32: =MIN(10, IF(N32="ativa",5,IF(N32="nova",4,IF(N32="esfriando",2,0)))+IF(L32>=9,3,IF(L32>=3,2,IF(L32>=1,1,0)))+IF(M32>=60,1.5,IF(M32>=30,1,IF(M32>=14,0.5,0)))+IF(V32>=50,1.5,IF(V32>=10,1,IF(V32>=1,0.5,0)))+IF(W32>=4,0.5,0)) -> 4 | C32: =ROUND(AC32*0.15+AD32*0.25+AE32*0.4+AF32*0.2,1) -> 6.7 | D32: =ROUND(B32*0.45+C32*0.55,1) -> 5.5 | E32: =IF(D32>=7,"Alta",IF(D32>=5,"Media","Baixa")) -> Media | F32: par-sketch.app | G32: 1 | H32: retrato-alma-gemea | I32: 3 | J32: abrir pagina | K32: buscar na biblioteca | L32: 0 | M32: 0 | N32: nova | O32: observar | P32: esoterico | Q32: retrato-alma-gemea | R32: 0 | S32: 0 | T32: 0.97 | U32: desconhecido | V32: 0 | W32: 1 | X32: 2026-08-30 | Y32: 2026-08-30 | Z32: servico-digital | AA32: nao | AB32: Angulo | AC32: 0 | AD32: 9 | AE32: 9 | AF32: 4 | AH32: # Angulo — Quiz de 60s que gera o retrato
A33: Brumdance 3 em 1 — ballet, jazz e contemporaneo para ministrar | B33: =MIN(10, IF(N33="ativa",5,IF(N33="nova",4,IF(N33="esfriando",2,0)))+IF(L33>=9,3,IF(L33>=3,2,IF(L33>=1,1,0)))+IF(M33>=60,1.5,IF(M33>=30,1,IF(M33>=14,0.5,0)))+IF(V33>=50,1.5,IF(V33>=10,1,IF(V33>=1,0.5,0)))+IF(W33>=4,0.5,0)) -> 6 | C33: =ROUND(AC33*0.15+AD33*0.25+AE33*0.4+AF33*0.2,1) -> 4.7 | D33: =ROUND(B33*0.45+C33*0.55,1) -> 5.3 | E33: =IF(D33>=7,"Alta",IF(D33>=5,"Media","Baixa")) -> Media | F33: brumdance.com.br | G33: 1 | H33: danca-gospel-ministerio | I33: 3 | J33: abrir pagina | K33: anuncio 1 criativo(s) | L33: 1 | M33: 30 | N33: nova | O33: observar | P33: danca | Q33: danca-gospel-ministerio | R33: 40 | S33: 120 | T33: 0.85 | U33: hotmart | V33: 0 | W33: 1 | X33: 2026-09-06 | Y33: 2026-09-06 | Z33: curso | AA33: sim | AB33: Oferta | AC33: 8 | AD33: 5 | AE33: 3 | AF33: 5 | AG33: Brumdance | AH33: # Brumdance 3 em 1
A34: Arquivos STL para impressao 3D | B34: =MIN(10, IF(N34="ativa",5,IF(N34="nova",4,IF(N34="esfriando",2,0)))+IF(L34>=9,3,IF(L34>=3,2,IF(L34>=1,1,0)))+IF(M34>=60,1.5,IF(M34>=30,1,IF(M34>=14,0.5,0)))+IF(V34>=50,1.5,IF(V34>=10,1,IF(V34>=1,0.5,0)))+IF(W34>=4,0.5,0)) -> 3 | C34: =ROUND(AC34*0.15+AD34*0.25+AE34*0.4+AF34*0.2,1) -> 7.2 | D34: =ROUND(B34*0.45+C34*0.55,1) -> 5.3 | E34: =IF(D34>=7,"Alta",IF(D34>=5,"Media","Baixa")) -> Media | F34: busca: arquivos STL impressao 3D | G34: 1 | H34: impressao-3d | I34: 1 | J34: — | K34: buscar na biblioteca | L34: 0 | M34: 0 | N34: esfriando | O34: replicar | P34: artesanato-e-pdf | Q34: impressao-3d | R34: 30 | S34: 30 | T34: 0.85 | U34: wiapy | V34: 4 | W34: 5 | X34: 2026-08-16 | Y34: 2026-08-27 | Z34: ebook | AA34: nao | AB34: Angulo | AC34: 4 | AD34: 7 | AE34: 8 | AF34: 8 | AH34: # Arquivos STL para impressao 3D
A35: Angulo — bonecas e cenarios de papel imprimiveis | B35: =MIN(10, IF(N35="ativa",5,IF(N35="nova",4,IF(N35="esfriando",2,0)))+IF(L35>=9,3,IF(L35>=3,2,IF(L35>=1,1,0)))+IF(M35>=60,1.5,IF(M35>=30,1,IF(M35>=14,0.5,0)))+IF(V35>=50,1.5,IF(V35>=10,1,IF(V35>=1,0.5,0)))+IF(W35>=4,0.5,0)) -> 4 | C35: =ROUND(AC35*0.15+AD35*0.25+AE35*0.4+AF35*0.2,1) -> 6.4 | D35: =ROUND(B35*0.45+C35*0.55,1) -> 5.3 | E35: =IF(D35>=7,"Alta",IF(D35>=5,"Media","Baixa")) -> Media | F35: busca: bonecas de papel | G35: 1 | H35: imprimivel-brincadeira | I35: 4 | J35: — | K35: buscar na biblioteca | L35: 0 | M35: 0 | N35: nova | O35: observar | P35: comportamento-infantil | Q35: imprimivel-brincadeira | R35: 0 | S35: 0 | T35: 0.9 | U35: desconhecido | V35: 0 | W35: 1 | X35: 2026-08-31 | Y35: 2026-08-31 | Z35: ebook | AA35: nao | AB35: Angulo | AC35: 0 | AD35: 8 | AE35: 10 | AF35: 2 | AH35: # Angulo — bonecas e cenarios de papel imprimiveis
A36: Angulo — caligrafia e grafismo imprimivel | B36: =MIN(10, IF(N36="ativa",5,IF(N36="nova",4,IF(N36="esfriando",2,0)))+IF(L36>=9,3,IF(L36>=3,2,IF(L36>=1,1,0)))+IF(M36>=60,1.5,IF(M36>=30,1,IF(M36>=14,0.5,0)))+IF(V36>=50,1.5,IF(V36>=10,1,IF(V36>=1,0.5,0)))+IF(W36>=4,0.5,0)) -> 4 | C36: =ROUND(AC36*0.15+AD36*0.25+AE36*0.4+AF36*0.2,1) -> 6.5 | D36: =ROUND(B36*0.45+C36*0.55,1) -> 5.4 | E36: =IF(D36>=7,"Alta",IF(D36>=5,"Media","Baixa")) -> Media | F36: busca: caligrafia | G36: 1 | H36: caligrafia | I36: 4 | J36: — | K36: buscar na biblioteca | L36: 0 | M36: 0 | N36: nova | O36: observar | P36: material-pedagogico | Q36: caligrafia | R36: 0 | S36: 0 | T36: 0.9 | U36: desconhecido | V36: 0 | W36: 1 | X36: 2026-08-31 | Y36: 2026-08-31 | Z36: ebook | AA36: nao | AB36: Angulo | AC36: 0 | AD36: 9 | AE36: 9 | AF36: 3 | AH36: # Angulo — caligrafia e grafismo imprimivel
A37: Certifica Brasil — prova online, certificado pago | B37: =MIN(10, IF(N37="ativa",5,IF(N37="nova",4,IF(N37="esfriando",2,0)))+IF(L37>=9,3,IF(L37>=3,2,IF(L37>=1,1,0)))+IF(M37>=60,1.5,IF(M37>=30,1,IF(M37>=14,0.5,0)))+IF(V37>=50,1.5,IF(V37>=10,1,IF(V37>=1,0.5,0)))+IF(W37>=4,0.5,0)) -> 6 | C37: =ROUND(AC37*0.15+AD37*0.25+AE37*0.4+AF37*0.2,1) -> 4.8 | D37: =ROUND(B37*0.45+C37*0.55,1) -> 5.3 | E37: =IF(D37>=7,"Alta",IF(D37>=5,"Media","Baixa")) -> Media | F37: busca: certifica brasil | G37: 1 | H37: taxa-para-liberar-certificado | I37: 4 | J37: — | K37: buscar na biblioteca | L37: 0 | M37: 0 | N37: ativa | O37: observar | P37: certificacao | Q37: taxa-para-liberar-certificado | R37: 0 | S37: 0 | T37: 0.95 | U37: desconhecido | V37: 13 | W37: 2 | X37: 2026-08-29 | Y37: 2026-08-30 | Z37: ebook | AA37: nao | AB37: Oferta | AC37: 0 | AD37: 8 | AE37: 5 | AF37: 4 | AH37: # Certifica Brasil — prova online, certificado pago
A38: Movimentos de Adoracao — 40 coreografias gospel prontas | B38: =MIN(10, IF(N38="ativa",5,IF(N38="nova",4,IF(N38="esfriando",2,0)))+IF(L38>=9,3,IF(L38>=3,2,IF(L38>=1,1,0)))+IF(M38>=60,1.5,IF(M38>=30,1,IF(M38>=14,0.5,0)))+IF(V38>=50,1.5,IF(V38>=10,1,IF(V38>=1,0.5,0)))+IF(W38>=4,0.5,0)) -> 5 | C38: =ROUND(AC38*0.15+AD38*0.25+AE38*0.4+AF38*0.2,1) -> 5.6 | D38: =ROUND(B38*0.45+C38*0.55,1) -> 5.3 | E38: =IF(D38>=7,"Alta",IF(D38>=5,"Media","Baixa")) -> Media | F38: dancalouvor.com | G38: 1 | H38: danca-gospel-ministerio | I38: 3 | J38: abrir pagina | K38: anuncio 2 criativo(s) | L38: 2 | M38: 4 | N38: nova | O38: observar | P38: danca | Q38: danca-gospel-ministerio | R38: 19.9 | S38: 25 | T38: 0.92 | U38: kiwify | V38: 0 | W38: 1 | X38: 2026-09-06 | Y38: 2026-09-06 | Z38: ebook | AA38: nao | AB38: Oferta | AC38: 3 | AD38: 2 | AE38: 9 | AF38: 5 | AG38: Coreografias Gospel | AH38: # Movimentos de Adoracao — 40 coreografias gospel prontas
A39: Angulo — curso gratis, certificado pago | B39: =MIN(10, IF(N39="ativa",5,IF(N39="nova",4,IF(N39="esfriando",2,0)))+IF(L39>=9,3,IF(L39>=3,2,IF(L39>=1,1,0)))+IF(M39>=60,1.5,IF(M39>=30,1,IF(M39>=14,0.5,0)))+IF(V39>=50,1.5,IF(V39>=10,1,IF(V39>=1,0.5,0)))+IF(W39>=4,0.5,0)) -> 5 | C39: =ROUND(AC39*0.15+AD39*0.25+AE39*0.4+AF39*0.2,1) -> 5.5 | D39: =ROUND(B39*0.45+C39*0.55,1) -> 5.3 | E39: =IF(D39>=7,"Alta",IF(D39>=5,"Media","Baixa")) -> Media | F39: busca: curso gratuito com certificado | G39: 1 | H39: taxa-para-liberar-certificado | I39: 4 | J39: — | K39: buscar na biblioteca | L39: 0 | M39: 0 | N39: ativa | O39: observar | P39: certificacao | Q39: taxa-para-liberar-certificado | R39: 139.9 | S39: 139.9 | T39: 0.95 | U39: desconhecido | V39: 0 | W39: 2 | X39: 2026-08-29 | Y39: 2026-08-30 | Z39: curso, ebook | AA39: nao | AB39: Angulo | AC39: 9 | AD39: 6 | AE39: 5 | AF39: 3 | AH39: # Angulo — curso gratis, certificado pago
A40: Hinário em Movimento | B40: =MIN(10, IF(N40="ativa",5,IF(N40="nova",4,IF(N40="esfriando",2,0)))+IF(L40>=9,3,IF(L40>=3,2,IF(L40>=1,1,0)))+IF(M40>=60,1.5,IF(M40>=30,1,IF(M40>=14,0.5,0)))+IF(V40>=50,1.5,IF(V40>=10,1,IF(V40>=1,0.5,0)))+IF(W40>=4,0.5,0)) -> 2.5 | C40: =ROUND(AC40*0.15+AD40*0.25+AE40*0.4+AF40*0.2,1) -> 7.3 | D40: =ROUND(B40*0.45+C40*0.55,1) -> 5.1 | E40: =IF(D40>=7,"Alta",IF(D40>=5,"Media","Baixa")) -> Media | F40: busca: Hinário em Movimento | G40: 1 | H40: gospel-louvor | I40: 1 | J40: — | K40: buscar na biblioteca | L40: 0 | M40: 0 | N40: esfriando | O40: observar | P40: religioso | Q40: gospel-louvor | R40: 0 | S40: 27 | T40: 0.85 | U40: lastlink | V40: 2 | W40: 2 | X40: 2026-08-16 | Y40: 2026-08-22 | AA40: nao | AB40: Oferta | AC40: 4 | AD40: 6 | AE40: 9 | AF40: 8 | AH40: # Hinário em Movimento
...

Sheet Grupos
A1: AGRUPAMENTOS — quem aponta pro mesmo lugar e quem esta vendendo a mesma coisa
A3: 1. Mesma oferta / mesmo angulo (clusters com 2 ou mais)
A4: Cluster | B4: Ofertas | C4: Nota geral (max) | D4: Nota geral (media) | E4: Criativos ativos (soma) | F4: Quais ofertas
A5: birra-disciplina | B5: 5 | C5: 3.8 | D5: =IFERROR(ROUND(AVERAGEIF(Ofertas!$H$2:$H$124,$A5,Ofertas!$D$2:$D$124),1),"") -> 3.5 | E5: =SUMIF(Ofertas!$H$2:$H$124,$A5,Ofertas!$L$2:$L$124) -> 0 | F5: Ângulo — Birra, teimosia e filho que não obedece | Ângulo — Pare de gritar com seu filho | Domando a Teimosia | Disciplina Positiva em Casa — eBook + 40 modelos de rotina | Pare de Gritar com seu Filho — Bia Arcangeli
A6: imprimivel-brincadeira | B6: 4 | C6: 7.4 | D6: =IFERROR(ROUND(AVERAGEIF(Ofertas!$H$2:$H$124,$A6,Ofertas!$D$2:$D$124),1),"") -> 6.3 | E6: =SUMIF(Ofertas!$H$2:$H$124,$A6,Ofertas!$L$2:$L$124) -> 12 | F6: +150 Bonecas de Papel — Maria Criativa | Casinha dos Sonhos — casinha de papel imprimivel | Kit Mundinho de Papel | Angulo — bonecas e cenarios de papel imprimiveis
A7: caligrafia | B7: 4 | C7: 7.1 | D7: =IFERROR(ROUND(AVERAGEIF(Ofertas!$H$2:$H$124,$A7,Ofertas!$D$2:$D$124),1),"") -> 6 | E7: =SUMIF(Ofertas!$H$2:$H$124,$A7,Ofertas!$L$2:$L$124) -> 10 | F7: Colecao Completa de Caligrafia 1o ao 6o ano — 380 atividades | Caderno Completo de Caligrafia — +300 atividades | Kit Do Rabisco a Letra Bonita — Uiara Oliveira | Angulo — caligrafia e grafismo imprimivel
A8: alfabetizacao | B8: 4 | C8: 6.9 | D8: =IFERROR(ROUND(AVERAGEIF(Ofertas!$H$2:$H$124,$A8,Ofertas!$D$2:$D$124),1),"") -> 5.2 | E8: =SUMIF(Ofertas!$H$2:$H$124,$A8,Ofertas!$L$2:$L$124) -> 12 | F8: Kit Grafismo Fonetico — Leitura Facil | Kit de Alfabetizacao Alfa Kids — 2.750 atividades | Ângulo — Criança que não aprende a ler | Método NeuroOctoMusical (Pipo) — alfabetização por sílabas
A9: taxa-para-liberar-certificado | B9: 4 | C9: 6.1 | D9: =IFERROR(ROUND(AVERAGEIF(Ofertas!$H$2:$H$124,$A9,Ofertas!$D$2:$D$124),1),"") -> 5.6 | E9: =SUMIF(Ofertas!$H$2:$H$124,$A9,Ofertas!$L$2:$L$124) -> 0 | F9: Cursos Gratis Online | Certificado Curso Online — curso gratis, certificado R$ 139,90 | Certifica Brasil — prova online, certificado pago | Angulo — curso gratis, certificado pago
A10: retrato-alma-gemea | B10: 3 | C10: 7.2 | D10: =IFERROR(ROUND(AVERAGEIF(Ofertas!$H$2:$H$124,$A10,Ofertas!$D$2:$D$124),1),"") -> 6.2 | E10: =SUMIF(Ofertas!$H$2:$H$124,$A10,Ofertas!$L$2:$L$124) -> 0 | F10: Retrato da Alma Gemea | The Soulmate Sketcher | Angulo - Quiz de 60s que gera o retrato
A11: taxa-para-liberar | B11: 3 | C11: 6 | D11: =IFERROR(ROUND(AVERAGEIF(Ofertas!$H$2:$H$124,$A11,Ofertas!$D$2:$D$124),1),"") -> 4.8 | E11: =SUMIF(Ofertas!$H$2:$H$124,$A11,Ofertas!$L$2:$L$124) -> 0 | F11: Google Captcha (TW Empreendimentos Digitais) | Escada de taxas decrescentes no pos-compra (nome nao capturado) | Love Pix
A12: danca-gospel-ministerio | B12: 3 | C12: 5.8 | D12: =IFERROR(ROUND(AVERAGEIF(Ofertas!$H$2:$H$124,$A12,Ofertas!$D$2:$D$124),1),"") -> 5.5 | E12: =SUMIF(Ofertas!$H$2:$H$124,$A12,Ofertas!$L$2:$L$124) -> 6 | F12: Dicionario em Movimento — 90 movimentos para ministracao | Brumdance 3 em 1 — ballet, jazz e contemporaneo para ministrar | Movimentos de Adoracao — 40 coreografias gospel prontas
A13: tea-autismo | B13: 3 | C13: 3.9 | D13: =IFERROR(ROUND(AVERAGEIF(Ofertas!$H$2:$H$124,$A13,Ofertas!$D$2:$D$124),1),"") -> 3.5 | E13: =SUMIF(Ofertas!$H$2:$H$124,$A13,Ofertas!$L$2:$L$124) -> 0 | F13: Ângulo — Kit imprimível para criança com TEA | Kit Só Escola Autismo — 650 páginas, 11 apostilas | TEA Sem Crise — Dr. Fábio Coelho
A14: devocional-diario | B14: 3 | C14: 3.9 | D14: =IFERROR(ROUND(AVERAGEIF(Ofertas!$H$2:$H$124,$A14,Ofertas!$D$2:$D$124),1),"") -> 3.8 | E14: =SUMIF(Ofertas!$H$2:$H$124,$A14,Ofertas!$L$2:$L$124) -> 0 | F14: Desafio 21 Dias com Deus (clone .shop) | Desafio 21 Dias com Deus (Traco Home) | Desafio de 30 Dias com Deus
A15: material-para-professora-de-ballet | B15: 2 | C15: 6.6 | D15: =IFERROR(ROUND(AVERAGEIF(Ofertas!$H$2:$H$124,$A15,Ofertas!$D$2:$D$124),1),"") -> 6.1 | E15: =SUMIF(Ofertas!$H$2:$H$124,$A15,Ofertas!$L$2:$L$124) -> 13 | F15: Cantigas da Bailarina — repertorio pronto para Baby Class | 250 Dinamicas de Ballet Prontas para Professoras
A16: acervo-professora | B16: 2 | C16: 6.3 | D16: =IFERROR(ROUND(AVERAGEIF(Ofertas!$H$2:$H$124,$A16,Ofertas!$D$2:$D$124),1),"") -> 6.1 | E16: =SUMIF(Ofertas!$H$2:$H$124,$A16,Ofertas!$L$2:$L$124) -> 2 | F16: Clube da Pedagogia — kit 3.000+ atividades BNCC | Licao Kids — loja de atividades imprimiveis
... A24: cura-interior | B24: 2 | C24: 3.7 | D24: =IFERROR(ROUND(AVERAGEIF(Ofertas!$H$2:$H$124,$A24,Ofertas!$D$2:$D$124),1),"") -> 3.7 | E24: =SUMIF(Ofertas!$H$2:$H$124,$A24,Ofertas!$L$2:$L$124) -> 0 | F24: Cura da Alma — devocional diario para traumas e feridas | Devocional com Proposito para Mulheres — 30 Dias de Cura Interior
A26: 2. Mesmo link de destino (mesma pagina de vendas ou mesmo termo de anuncio)
A27: Grupo (destino) | B27: Ofertas | C27: Nota geral (max) | D27: Criativos ativos (soma) | E27: Quais ofertas | F27: Tipo de agrupamento
A28: hotmart.com | B28: 3 | C28: 3.7 | D28: =SUMIF(Ofertas!$F$2:$F$124,$A28,Ofertas!$L$2:$L$124) -> 0 | E28: Cura da Alma — devocional diario para traumas e feridas | Devocional 15 dias — Para quem sofre de ansiedade | Devocional com Proposito para Mulheres — 30 Dias de Cura Interior | F28: mesma pagina de vendas
A29: dancadosnoivosonline.com | B29: 1 | C29: 7.5 | D29: =SUMIF(Ofertas!$F$2:$F$124,$A29,Ofertas!$L$2:$L$124) -> 9 | E29: Danca dos Noivos Online | F29: mesma pagina de vendas
A30: bonecasdepapel28.lovable.app | B30: 1 | C30: 7.4 | D30: =SUMIF(Ofertas!$F$2:$F$124,$A30,Ofertas!$L$2:$L$124) -> 9 | E30: +150 Bonecas de Papel — Maria Criativa | F30: mesma pagina de vendas
A31: alldigital.fun | B31: 1 | C31: 7.2 | D31: =SUMIF(Ofertas!$F$2:$F$124,$A31,Ofertas!$L$2:$L$124) -> 0 | E31: Retrato da Alma Gemea | F31: mesma pagina de vendas
A32: atividade-cursiva.netlify.app | B32: 1 | C32: 7.1 | D32: =SUMIF(Ofertas!$F$2:$F$124,$A32,Ofertas!$L$2:$L$124) -> 8 | E32: Colecao Completa de Caligrafia 1o ao 6o ano — 380 atividades | F32: mesma pagina de vendas
A33: thelittlegenius.com.br | B33: 1 | C33: 7.1 | D33: =SUMIF(Ofertas!$F$2:$F$124,$A33,Ofertas!$L$2:$L$124) -> 1 | E33: Little Genius — Kit de 235+ atividades educativas | F33: mesma pagina de vendas
A34: busca: grafismo fonetico | B34: 1 | C34: 6.9 | D34: =SUMIF(Ofertas!$F$2:$F$124,$A34,Ofertas!$L$2:$L$124) -> 10 | E34: Kit Grafismo Fonetico — Leitura Facil | F34: mesmo termo na Biblioteca
A35: busca: missa em atividades | B35: 1 | C35: 6.8 | D35: =SUMIF(Ofertas!$F$2:$F$124,$A35,Ofertas!$L$2:$L$124) -> 3 | E35: Missa em Atividades — kit catolico infantil imprimivel | F35: mesmo termo na Biblioteca
A36: ballerinalab.com.br | B36: 1 | C36: 6.6 | D36: =SUMIF(Ofertas!$F$2:$F$124,$A36,Ofertas!$L$2:$L$124) -> 11 | E36: Cantigas da Bailarina — repertorio pronto para Baby Class | F36: mesma pagina de vendas
A37: busca: coreografias prontas | B37: 1 | C37: 6.6 | D37: =SUMIF(Ofertas!$F$2:$F$124,$A37,Ofertas!$L$2:$L$124) -> 19 | E37: Angulo — material pronto para quem ENSINA danca | F37: mesmo termo na Biblioteca
A38: casinhadossonhos.com.br | B38: 1 | C38: 6.5 | D38: =SUMIF(Ofertas!$F$2:$F$124,$A38,Ofertas!$L$2:$L$124) -> 2 | E38: Casinha dos Sonhos — casinha de papel imprimivel | F38: mesma pagina de vendas
